// const fnWithError = () => {
//   // функція яка генерує якусь помилку
//   throw new Error("Some error");
// };
// fnWithError(); // uncaught помилка, після цього робота програми зупиняється
// console.log("Continue..."); // не побачимо цю команду, через попередню помилку

// try/catch
// try {
// //виконання блоку кода
// } catch (error) {
// //цей блок виконується у випадку винекнення помилки в блоці try
// }
